<?xml version="1.0"?>
<robot name="my_robot">
  <link name="base_link">
    <visual>
      <origin rpy="0 0 0" xyz="0 0 0"/>
      <geometry>
        <mesh filename="package://robot_description/stl/chassis.stl"/>
      </geometry>
    </visual>
  </link>
  <link name="left_wheel">
    <visual>
      <origin rpy="0 0 0" xyz="0.1065 0.048 0"/>
      <geometry>
        <mesh filename="package://robot_description/stl/wheel.stl"/>
      </geometry>
    </visual>
  </link>
  <link name="right_wheel">
    <visual>
      <origin rpy="0 0 0" xyz="-0.1065 0.048 0"/>
      <geometry>
        <mesh filename="package://robot_description/stl/wheel.stl"/>
      </geometry>
    </visual>
  </link>
  <link name="caster_wheel">
    <visual>
      <origin rpy="0 0 0" xyz="0 0 0"/>
      <geometry>
        <cylinder length="0.03" radius="0.01"/>
      </geometry>
    </visual>
  </link>
  <joint name="left_wheel_joint" type="continuous">
    <origin xyz="0.1065 0.048 0"/>
    <parent link="base_link"/>
    <child link="left_wheel"/>
    <axis xyz="0 0 1"/>
  </joint>
  <joint name="right_wheel_joint" type="continuous">
    <origin xyz="-0.1065 0.048 0"/>
    <parent link="base_link"/>
    <child link="right_wheel"/>
    <axis xyz="0 0 1"/>
  </joint>
  <joint name="caster_joint1" type="fixed">
    <origin xyz="0.12 0.0 -0.02"/>
    <parent link="base_link"/>
    <child link="caster_mount1"/>
  </joint>
  <joint name="caster_joint2" type="fixed">
    <origin xyz="-0.12 0.0 -0.02"/>
    <parent link="base_link"/>
    <child link="caster_mount2"/>
  </joint>
  <joint name="caster_mount1_joint" type="fixed">
    <origin xyz="0 0 0"/>
    <parent link="caster_mount1"/>
    <child link="caster_wheel"/>
  </joint>
  <joint name="caster_mount2_joint" type="fixed">
    <origin xyz="0 0 0"/>
    <parent link="caster_mount2"/>
    <child link="caster_wheel"/>
  </joint>
  <link name="caster_mount1">
    <visual>
      <origin rpy="0 0 0" xyz="0 0 0"/>
      <geometry>
        <box size="0.03 0.02 0.01"/>
      </geometry>
    </visual>
  </link>
  <link name="caster_mount2">
    <visual>
      <origin rpy="0 0 0" xyz="0 0 0"/>
      <geometry>
        <box size="0.03 0.02 0.01"/>
      </geometry>
    </visual>
  </link>
</robot>

